Traceback (most recent call last):
  File "/zhome/0a/b/138401/Desktop/Apart/Multi-Lingual-Jailbreaks/env/lib/python3.10/site-packages/transformers/utils/hub.py", line 399, in cached_file
    resolved_file = hf_hub_download(
  File "/zhome/0a/b/138401/Desktop/Apart/Multi-Lingual-Jailbreaks/env/lib/python3.10/site-packages/huggingface_hub/utils/_validators.py", line 106, in _inner_fn
    validate_repo_id(arg_value)
  File "/zhome/0a/b/138401/Desktop/Apart/Multi-Lingual-Jailbreaks/env/lib/python3.10/site-packages/huggingface_hub/utils/_validators.py", line 154, in validate_repo_id
    raise HFValidationError(
huggingface_hub.errors.HFValidationError: Repo id must be in the form 'repo_name' or 'namespace/repo_name': '/dtu/blackhole/01/138401/nllb600M'. Use `repo_type` argument if needed.

The above exception was the direct cause of the following exception:

Traceback (most recent call last):
  File "/zhome/0a/b/138401/Desktop/Apart/Multi-Lingual-Jailbreaks/pipeline.py", line 198, in <module>
    translation_pipeline(data_original, translation_model, language,cut_off=0)
  File "/zhome/0a/b/138401/Desktop/Apart/Multi-Lingual-Jailbreaks/pipeline.py", line 28, in translation_pipeline
    model = NLLB.nllb_translator(model_name)
  File "/zhome/0a/b/138401/Desktop/Apart/Multi-Lingual-Jailbreaks/NLLB.py", line 61, in __init__
    self.model = AutoModelForSeq2SeqLM.from_pretrained(os.path.join(model_folder,model_name))
  File "/zhome/0a/b/138401/Desktop/Apart/Multi-Lingual-Jailbreaks/env/lib/python3.10/site-packages/transformers/models/auto/auto_factory.py", line 484, in from_pretrained
    resolved_config_file = cached_file(
  File "/zhome/0a/b/138401/Desktop/Apart/Multi-Lingual-Jailbreaks/env/lib/python3.10/site-packages/transformers/utils/hub.py", line 463, in cached_file
    raise EnvironmentError(
OSError: Incorrect path_or_model_id: '/dtu/blackhole/01/138401/nllb600M'. Please provide either the path to a local folder or the repo_id of a model on the Hub.
